Workbook
Name DATAFILNAVN: '[1]L Basis sokkel'!$C$2
Name DATAARK2: '[1]A Innh'!$P$7

Sheet SNKS
B3: 2007 | C3: 2008 | D3: 2009 | E3: 2010 | F3: 2011 | G3: 2012 | H3: 2013 | I3: 2014 | J3: 2015 | K3: 2016 | L3: 2017 | M3: 2018 | N3: 2019 | O3: 2020 | P3: 2021 | Q3: 2022 | R3: 2023 | S3: 2024 | T3: 2025 | U3: 2026 | V3: 2027 | W3: 2028 | X3: 2029 | Y3: 2030 | Z3: 2031 | AA3: 2032 | AB3: 2033 | AC3: 2034 | AD3: 2035 | AE3: 2036 | AF3: 2037 | AG3: 2038 | AH3: 2039 | AI3: 2040 | AJ3: 2041 | AK3: 2042 | AL3: 2043 | AM3: 2044 | AN3: 2045 | AO3: 2046 | AP3: 2047 | AQ3: 2048 | AR3: 2049 | AS3: 2050 | AT3: 2051 | AU3: 2052 | AV3: 2053 | AW3: 2054 | AX3: 2055 | AY3: 2056 | AZ3: 2057 | BA3: 2058 | BB3: 2059 | BC3: 2060 | BD3: 2061 | BE3: 2062 | BF3: 2063 | BG3: 2064 | BH3: 2065 | BI3: 2066 | BJ3: 2067 | BK3: 2068 | BL3: 2069 | BM3: 2070 | BN3: 2071 | BO3: 2072 | BP3: 2073 | BQ3: 2074 | BR3: 2075 | BS3: 2076 | BT3: 2077 | BU3: 2078 | BV3: 2079 | BW3: 2080 | BX3: 2081 | BY3: 2082 | BZ3: 2083 | CA3: 2084 | CB3: 2085 | CC3: 2086 | CD3: 2087 | CE3: 2088 | CF3: 2089 | CG3: 2090
A4: OEDs anslag på påløpte skatter og avgifter
A5: Ordinær inntektsskatt (Påløpt) | I5: 60138 | J5: 37796 | K5: 21816 | L5: 34261.815 | M5: 51315 | N5: 36861.546 | O5: 18353.446 | P5: 100738.24 | Q5: 278750.99 | R5: 148738.99 | S5: 123447.59 | T5: 113057.81 | U5: 79111.769 | V5: 61731.884 | W5: 53717.917 | X5: 48154.134 | Y5: 33976.939 | Z5: 34056.2 | AA5: 34943.587 | AB5: 35075.418 | AC5: 37388.296 | AD5: 39542.572 | AE5: 40283.955 | AF5: 38056.097 | AG5: 34508.552 | AH5: 32815.23 | AI5: 31607.413 | AJ5: 30416.088 | AK5: 27739.584 | AL5: 26647.806 | AM5: 24967.08 | AN5: 23170.601 | AO5: 21911.493 | AP5: 20928.576 | AQ5: 21671.312 | AR5: 21645.065 | AS5: 20456.332 | AT5: 20912.886 | AU5: 18907.424 | AV5: 17694.763 | AW5: 16332.818 | AX5: 15475.962 | AY5: 16093.912 | AZ5: 15911.787 | BA5: 13614.459 | BB5: 12898.107 | BC5: 11809.592
A6: Særskatt (Påløpt) | I6: 98701 | J6: 58513 | K6: 35058 | L6: 63762.704 | M6: 105445 | N6: 84676.523 | O6: -30102.969 | P6: 193549.05 | Q6: 659385.81 | R6: 319897.55 | S6: 260941.74 | T6: 242277.94 | U6: 185567.5 | V6: 164146.87 | W6: 164228.33 | X6: 151850.93 | Y6: 114611.77 | Z6: 110678.25 | AA6: 106452.01 | AB6: 101299.1 | AC6: 108538.28 | AD6: 115480.14 | AE6: 118072.07 | AF6: 113048.9 | AG6: 103083.11 | AH6: 95480.587 | AI6: 88453.795 | AJ6: 85172.445 | AK6: 77329.305 | AL6: 74578.952 | AM6: 70614.447 | AN6: 67073.079 | AO6: 65724.433 | AP6: 61674.244 | AQ6: 63705.011 | AR6: 63265.488 | AS6: 61603.7 | AT6: 63433.239 | AU6: 59597.941 | AV6: 56848.161 | AW6: 52090.024 | AX6: 50654.628 | AY6: 53350.643 | AZ6: 52052.158 | BA6: 44396.377 | BB6: 43820.687 | BC6: 40229.363
A7: Refusjon mot underskudd særskatt | I7: -3805 | J7: -4305 | K7: -2297 | L7: -1992.3761 | M7: -1197 | N7: -1334.5978 | O7: -133.39073 | P7: -2984.1693 | Q7: -2395.6757 | R7: -2702.9706 | S7: -3208.7847 | T7: -3323.468 | U7: -4708.1237 | V7: -3186.109 | W7: -7371.3867 | X7: -8976.0047 | Y7: -15239.473 | Z7: -6534.682 | AA7: -2464.9669 | AB7: -1935.8041 | AC7: -1093.75 | AD7: -1864.9611 | AE7: -2551.7804 | AF7: -2990.4797 | AG7: -3509.3018 | AH7: -2363.5832 | AI7: -1189.2626 | AJ7: -1860.6843 | AK7: -2077.9027 | AL7: -940.65841 | AM7: -950.87582 | AN7: -850.94092 | AO7: -167.95633 | AP7: -644.96991 | AQ7: -4021.3083 | AR7: -4932.3671 | AS7: -184.80182 | AT7: -548.34446 | AU7: -411.24236 | AV7: -482.9807 | AW7: -404.45942 | AX7: -269.99124 | AY7: -147.62065 | AZ7: -588.40853 | BA7: -2.7512848 | BB7: -258.59975 | BC7: -312.41288
A8: Refusjon ubenyttet friinntekt | I8: -7188 | J8: -8132 | K8: -4869 | L8: -5089.2217 | M8: -4332 | N8: -3445.0816 | O8: -161.50569 | P8: -1069.1184 | Q8: -216.96911 | R8: -80.724425 | S8: -66.774 | T8: -5396.2333 | U8: -4240.8334 | V8: -169.448 | W8: -18.668 | X8: 0 | Y8: 0 | Z8: 0 | AA8: 0 | AB8: 0 | AC8: 0 | AD8: 0 | AE8: 0 | AF8: 0 | AG8: 0 | AH8: 0 | AI8: 0 | AJ8: 0 | AK8: 0 | AL8: 0 | AM8: 0 | AN8: 0 | AO8: 0 | AP8: 0 | AQ8: 0 | AR8: 0 | AS8: 0 | AT8: 0 | AU8: 0 | AV8: 0 | AW8: 0 | AX8: 0 | AY8: 0 | AZ8: 0 | BA8: 0 | BB8: 0 | BC8: 0
A9: Produksjonsavgift | I9: 0 | J9: 0 | K9: 0 | L9: 0 | M9: 0 | N9: 0 | O9: 0 | P9: 0 | Q9: 0 | R9: 0 | S9: 0 | T9: 0 | U9: 0 | V9: 0 | W9: 0 | X9: 0 | Y9: 0 | Z9: 0 | AA9: 0 | AB9: 0 | AC9: 0 | AD9: 0 | AE9: 0 | AF9: 0 | AG9: 0 | AH9: 0 | AI9: 0 | AJ9: 0 | AK9: 0 | AL9: 0 | AM9: 0 | AN9: 0 | AO9: 0 | AP9: 0 | AQ9: 0 | AR9: 0 | AS9: 0
A10: Arealavgift | I10: 1766 | J10: 1636 | K10: 1500 | L10: 1359.4042 | M10: 1379.829 | N10: 1488.3013 | O10: 1508.6929 | P10: 1372.141 | Q10: 1209.3158 | R10: 1127.2039 | S10: 1382.3287 | T10: 1472.5541 | U10: 1624.6262 | V10: 1696.2214 | W10: 1879.5041 | X10: 1905.7279 | Y10: 1750.0413 | Z10: 1785.0421 | AA10: 1820.7429 | AB10: 1857.1578 | AC10: 1894.3009 | AD10: 1932.187 | AE10: 1970.8307 | AF10: 2010.2473 | AG10: 2050.4523 | AH10: 2091.4613 | AI10: 2133.2905 | AJ10: 2175.9563 | AK10: 2219.4755 | AL10: 2263.865 | AM10: 2309.1423 | AN10: 2355.3251 | AO10: 2402.4316 | AP10: 2450.4803 | AQ10: 2499.4899 | AR10: 2549.4797 | AS10: 2600.4693 | AT10: 2652.4786 | AU10: 2705.5282 | AV10: 2759.6388 | AW10: 2814.8315 | AX10: 2871.1282 | AY10: 2928.5507 | AZ10: 2987.1218 | BA10: 3046.8642 | BB10: 3107.8015 | BC10: 3169.9575
A11: NOx-avgift | I11: 0 | J11: 0 | K11: 0 | L11: 0 | M11: 0 | N11: 0 | O11: 0 | P11: 0 | Q11: 0 | R11: 0 | S11: 0 | T11: 0 | U11: 0 | V11: 0 | W11: 0 | X11: 0 | Y11: 0 | Z11: 0 | AA11: 0 | AB11: 0 | AC11: 0 | AD11: 0 | AE11: 0 | AF11: 0 | AG11: 0 | AH11: 0 | AI11: 0 | AJ11: 0 | AK11: 0 | AL11: 0 | AM11: 0 | AN11: 0 | AO11: 0 | AP11: 0 | AQ11: 0 | AR11: 0 | AS11: 0 | AT11: 0 | AU11: 0 | AV11: 0 | AW11: 0 | AX11: 0 | AY11: 0 | AZ11: 0 | BA11: 0 | BB11: 0 | BC11: 0
A12: CO2-avgift | I12: 4894 | J12: 5078 | K12: 5365 | L12: 5331.1906 | M12: 5650.0241 | N12: 5790.1281 | O12: 6031.9859 | P12: 5357.6102 | Q12: 7082.6807 | R12: 7586.9975 | S12: 7540.5543 | T12: 9253.362 | U12: 9597.2284 | V12: 9460.3313 | W12: 8459.0003 | X12: 7968.6141 | Y12: 11153.701 | Z12: 10592.486 | AA12: 9681.5216 | AB12: 9602.8419 | AC12: 9105.9987 | AD12: 8763.7091 | AE12: 8839.61 | AF12: 8771.796 | AG12: 8382.0078 | AH12: 8107.1451 | AI12: 7144.8301 | AJ12: 6382.6336 | AK12: 6387.2586 | AL12: 6123.787 | AM12: 5582.5922 | AN12: 4944.2153 | AO12: 4614.685 | AP12: 4447.84 | AQ12: 3953.3849 | AR12: 3678.6206 | AS12: 3399.1007 | AT12: 3351.4057 | AU12: 3563.7522 | AV12: 3616.8768 | AW12: 3324.1837 | AX12: 3331.772 | AY12: 3261.3247 | AZ12: 3293.9937 | BA12: 3396.8859 | BB12: 3229.877 | BC12: 3066.4823
A13: Totale skatter justert for refusjon | I13: =SUM(I5:I8) -> 147846 | J13: =SUM(J5:J8) -> 83872 | K13: =SUM(K5:K8) -> 49708 | L13: =SUM(L5:L8) -> 90942.921 | M13: =SUM(M5:M8) -> 151231 | N13: =SUM(N5:N8) -> 116758.39 | O13: =SUM(O5:O8) -> -12044.419 | P13: =SUM(P5:P8) -> 290234 | ... BC13: =SUM(BC5:BC8) -> 51726.542
A14: Totale avgifter | I14: =SUM(I9:I12) -> 6660 | J14: =SUM(J9:J12) -> 6714 | K14: =SUM(K9:K12) -> 6865 | L14: =SUM(L9:L12) -> 6690.5948 | M14: =SUM(M9:M12) -> 7029.8531 | N14: =SUM(N9:N12) -> 7278.4294 | O14: =SUM(O9:O12) -> 7540.6787 | P14: =SUM(P9:P12) -> 6729.7512 | ... BC14: =SUM(BC9:BC12) -> 6236.4398
A15: Sum skatter og avgifter | I15: =I13+I14 -> 154506 | J15: =J13+J14 -> 90586 | K15: =K13+K14 -> 56573 | L15: =L13+L14 -> 97633.516 | M15: =M13+M14 -> 158260.85 | N15: =N13+N14 -> 124036.82 | O15: =O13+O14 -> -4503.7405 | P15: =P13+P14 -> 296963.75 | ... BC15: =BC13+BC14 -> 57962.982
A18: FINs anslag på påløpte skatter og avgifter (Gul = Overprøving av OED)
A19: (avrundingsfaktor) | I19: 0 | J19: 0 | K19: 0 | L19: 0 | M19: 0 | N19: 0 | O19: 0 | P19: 0 | Q19: 0 | R19: 0 | S19: 0 | T19: 0 | U19: 0 | V19: 0 | W19: 0 | X19: 0 | Y19: 0 | Z19: 0 | AA19: 0 | AB19: 0 | AC19: 0 | AD19: 0 | AE19: 0 | AF19: 0 | AG19: 0 | AH19: 0 | AI19: 0 | AJ19: 0 | AK19: 0 | AL19: 0 | AM19: 0 | AN19: 0 | AO19: 0 | AP19: 0 | AQ19: 0 | AR19: 0 | AS19: 0 | AT19: 0 | AU19: 0 | AV19: 0 | AW19: 0 | AX19: 0 | AY19: 0 | AZ19: 0 | BA19: 0 | BB19: 0 | BC19: 0
A20: Income tax | I20: =I5 -> 60138 | J20: =J5 -> 37796 | K20: =K5 -> 21816 | L20: =L5 -> 34261.815 | M20: =M5 -> 51315 | N20: =N5 -> 36861.546 | O20: =O5 -> 18353.446 | P20: =P5 -> 100738.24 | ... S20: =S5 -> 123447.59 | T20: 107392 | U20: =U5 -> 79111.769 | V20: =V5 -> 61731.884 | W20: =W5 -> 53717.917 | X20: =X5 -> 48154.134 | Y20: =Y5 -> 33976.939 | Z20: =Z5 -> 34056.2 | AA20: =AA5 -> 34943.587 | AB20: =AB5 -> 35075.418 | ... BC20: =BC5 -> 11809.592
A21: Special petroleum tax | I21: =I6 -> 98701 | J21: =J6 -> 58513 | K21: =K6 -> 35058 | L21: =L6 -> 63762.704 | M21: =M6 -> 105445 | N21: =N6 -> 84676.523 | O21: =O6 -> -30102.969 | P21: =P6 -> 193549.05 | ... S21: =S6 -> 260941.74 | T21: 228208 | U21: =U6 -> 185567.5 | V21: =V6 -> 164146.87 | W21: =W6 -> 164228.33 | X21: =X6 -> 151850.93 | Y21: =Y6 -> 114611.77 | Z21: =Z6 -> 110678.25 | AA21: =AA6 -> 106452.01 | AB21: =AB6 -> 101299.1 | ... BC21: =BC6 -> 40229.363
A22: Refusjon mot underskudd særskatt | I22: =I7 -> -3805 | J22: =J7 -> -4305 | K22: =K7 -> -2297 | L22: =L7 -> -1992.3761 | M22: =M7 -> -1197 | N22: =N7 -> -1334.5978 | O22: =O7 -> -133.39073 | P22: =P7 -> -2984.1693 | ... BC22: =BC7 -> -312.41288
A23: Refusjon ubenyttet friinntekt | I23: =I8 -> -7188 | J23: =J8 -> -8132 | K23: =K8 -> -4869 | L23: =L8 -> -5089.2217 | M23: =M8 -> -4332 | N23: =N8 -> -3445.0816 | O23: =O8 -> -161.50569 | P23: =P8 -> -1069.1184 | ... BC23: =BC8 -> 0
A24: Produksjonsavgift | I24: =I9 -> 0 | J24: =J9 -> 0 | K24: =K9 -> 0 | L24: =L9 -> 0 | M24: =M9 -> 0 | N24: =N9 -> 0 | O24: =O9 -> 0 | P24: =P9 -> 0 | ... BC24: =BC9 -> 0
A25: Arealavgift | I25: =I10 -> 1766 | J25: =J10 -> 1636 | K25: =K10 -> 1500 | L25: =L10 -> 1359.4042 | M25: =M10 -> 1379.829 | N25: =N10 -> 1488.3013 | O25: =O10 -> 1508.6929 | P25: =P10 -> 1372.141 | ... BC25: =BC10 -> 3169.9575
A26: CO2-avgift | I26: =I12 -> 4894 | J26: =J12 -> 5078 | K26: =K12 -> 5365 | L26: =L12 -> 5331.1906 | M26: =M12 -> 5650.0241 | N26: =N12 -> 5790.1281 | O26: =O12 -> 6031.9859 | P26: =P12 -> 5357.6102 | ... BC26: =BC12 -> 3066.4823
A27: Nox-avgift | I27: =I11 -> 0 | J27: =J11 -> 0 | K27: =K11 -> 0 | L27: =L11 -> 0 | M27: =M11 -> 0 | N27: =N11 -> 0 | O27: =O11 -> 0 | P27: =P11 -> 0 | ... BC27: =BC11 -> 0
A30: Betalte skatter og avgifter
A31: Income tax | I31: 64212 | J31: 39476.659 | K31: 16034.226 | L31: 23688.095 | M31: 38539.517 | N31: 43011.141 | O31: 16724.759 | P31: 51982.827 | Q31: 212994.79 | R31: 188239.11 | S31: 132693.48 | T31: 121052.35 | U31: =(T20+U20)/2 -> 93251.884 | V31: =(U20+V20)/2 -> 70421.826 | W31: =(V20+W20)/2 -> 57724.9 | X31: =(W20+X20)/2 -> 50936.026 | Y31: =(X20+Y20)/2 -> 41065.537 | Z31: =(Y20+Z20)/2 -> 34016.569 | AA31: =(Z20+AA20)/2 -> 34499.893 | AB31: =(AA20+AB20)/2 -> 35009.502 | ... BC31: =(BB20+BC20)/2 -> 12353.85
A32: Special petroleum tax (adjusted for repayments) | I32: 105837 | J32: 64195.817 | K32: 25058.532 | L32: 41361 | M32: 71773.979 | N32: 90490.326 | O32: 11662.884 | P32: 33728.419 | Q32: 500626.49 | R32: 426187.36 | S32: 278773.96 | T32: 252819.61 | U32: =(T21+U21)/2+(T22+T23) -> 198168.05 | V32: =(U21+V21)/2+(U22+U23) -> 165908.23 | W32: =(V21+W21)/2+(V22+V23) -> 160832.04 | X32: =(W21+X21)/2+(W22+W23) -> 150649.57 | Y32: =(X21+Y21)/2+(X22+X23) -> 124255.34 | Z32: =(Y21+Z21)/2+(Y22+Y23) -> 97405.539 | AA32: =(Z21+AA21)/2+(Z22+Z23) -> 102030.45 | AB32: =(AA21+AB21)/2+(AA22+AA23) -> 101410.58 | ... BC32: =(BB21+BC21)/2+(BB22+BB23) -> 41766.425
A33: Produksjonsavgift | I33: =(1/12)*(H24)+(11/12)*(I24) -> 0 | J33: =(1/12)*(I24)+(11/12)*(J24) -> 0 | K33: =(1/12)*(J24)+(11/12)*(K24) -> 0 | L33: =(1/12)*(K24)+(11/12)*(L24) -> 0 | M33: =(1/12)*(L24)+(11/12)*(M24) -> 0 | N33: 0 | O33: =(1/12)*(N24)+(11/12)*(O24) -> 0 | P33: =(1/12)*(O24)+(11/12)*(P24) -> 0 | Q33: =(1/12)*(P24)+(11/12)*(Q24) -> 0 | R33: =(1/12)*(Q24)+(11/12)*(R24) -> 0 | S33: =(1/12)*(R24)+(11/12)*(S24) -> 0 | T33: =(1/12)*(S24)+(11/12)*(T24) -> 0 | U33: =(1/12)*(T24)+(11/12)*(U24) -> 0 | V33: =(1/12)*(U24)+(11/12)*(V24) -> 0 | ... BC33: =(1/12)*(BB24)+(11/12)*(BC24) -> 0
A34: Arealavgift | I34: 1535.8388 | J34: 1550.9334 | K34: 1403.3694 | L34: 939.15558 | M34: 1779.7733 | N34: 1504.9512 | O34: 1417.6332 | P34: 939.59585 | Q34: 1049.9071 | R34: 1319.4878 | S34: 1179.8897 | T34: =T25 -> 1472.5541 | U34: =U25 -> 1624.6262 | V34: =V25 -> 1696.2214 | W34: =W25 -> 1879.5041 | X34: =X25 -> 1905.7279 | Y34: =Y25 -> 1750.0413 | Z34: =Z25 -> 1785.0421 | AA34: =AA25 -> 1820.7429 | ... BC34: =BC25 -> 3169.9575
A35: CO2-avgift | I35: 4516.1052 | J35: 4959.4259 | K35: 5107.5202 | L35: 5181.9697 | M35: 5192.6893 | N35: 5370.9069 | O35: 5601.6462 | P35: 5197.2109 | Q35: 6258.3328 | R35: 7495.8174 | S35: 7694.7028 | T35: =(S26+T26)/2 -> 8396.9581 | U35: =(T26+U26)/2 -> 9425.2952 | V35: =(U26+V26)/2 -> 9528.7799 | W35: =(V26+W26)/2 -> 8959.6658 | X35: =(W26+X26)/2 -> 8213.8072 | Y35: =(X26+Y26)/2 -> 9561.1578 | Z35: =(Y26+Z26)/2 -> 10873.094 | AA35: =(Z26+AA26)/2 -> 10137.004 | ... BC35: =(BB26+BC26)/2 -> 3148.1796
A36: Nox-avgift | I36: 61.899116 | J36: -25.682537 | K36: 2.199846 | L36: 6.554682 | M36: 1.030437 | N36: 1.715724 | O36: 0.952288 | P36: 0.728023 | Q36: 1.447237 | R36: 3.649008 | S36: -2.624272 | T36: 1 | U36: 1 | V36: =0.25*U27+0.75*V27 -> 0 | W36: =0.25*V27+0.75*W27 -> 0 | X36: =0.25*W27+0.75*X27 -> 0 | Y36: =0.25*X27+0.75*Y27 -> 0 | Z36: =0.25*Y27+0.75*Z27 -> 0 | AA36: =0.25*Z27+0.75*AA27 -> 0 | AB36: =0.25*AA27+0.75*AB27 -> 0 | AC36: =0.25*AB27+0.75*AC27 -> 0 | ... BC36: =0.25*BB27+0.75*BC27 -> 0
A37: Sum skatter | I37: =I31+I32 -> 170049 | J37: =J31+J32 -> 103672.48 | K37: =K31+K32 -> 41092.758 | L37: =L31+L32 -> 65049.095 | M37: =M31+M32 -> 110313.5 | N37: =N31+N32 -> 133501.47 | O37: =O31+O32 -> 28387.643 | P37: =P31+P32 -> 85711.246 | ... BC37: =BC31+BC32 -> 54120.275
A38: Sum avgifter | I38: =I33+I34+I35+I36 -> 6113.8431 | J38: =J33+J34+J35+J36 -> 6484.6767 | K38: =K33+K34+K35+K36 -> 6513.0895 | L38: =L33+L34+L35+L36 -> 6127.6799 | M38: =M33+M34+M35+M36 -> 6973.4931 | N38: =N33+N34+N35+N36 -> 6877.5739 | O38: =O33+O34+O35+O36 -> 7020.2317 | P38: =P33+P34+P35+P36 -> 6137.5348 | ... BC38: =BC33+BC34+BC35+BC36 -> 6318.1372
A39: Sum skatter og avgifter | I39: =I37+I38 -> 176162.84 | J39: =J37+J38 -> 110157.15 | K39: =K37+K38 -> 47605.847 | L39: =L37+L38 -> 71176.775 | M39: =M37+M38 -> 117286.99 | N39: =N37+N38 -> 140379.04 | O39: =O37+O38 -> 35407.874 | P39: =P37+P38 -> 91848.781 | ... BC39: =BC37+BC38 -> 60438.412
A42: Provenyvirkning
A43: Særskatt (Påløpt) | I43: 0 | J43: 0 | K43: 0 | L43: 0 | M43: 0 | N43: 0 | O43: 0 | P43: 0 | Q43: 0 | R43: 0 | S43: 0 | T43: 0 | U43: 0 | V43: 0 | W43: 0
A44: Særskatt (Betalt) | I44: 0 | J44: 0 | K44: 0 | L44: 0 | M44: 0 | N44: 0 | O44: 0 | P44: 0 | Q44: 0 | R44: 0 | S44: 0 | T44: 0 | U44: 0 | V44: 0 | W44: 0
A51: Oppsummering av inntektsanslag fra petroleumssektoren
A53: Påløpte skatter og avgifter, avrundet, mill. kr.
A54: Income tax | I54: =I20+I22 -> 56333 | J54: =J20+J22 -> 33491 | K54: =K20+K22 -> 19519 | L54: =L20+L22 -> 32269.439 | M54: =M20+M22 -> 50118 | N54: =N20+N22 -> 35526.948 | O54: =O20+O22 -> 18220.055 | P54: =P20+P22 -> 97754.066 | ... S54: =S20+S22 -> 120238.8 | T54: =ROUND((T20)/100,T$66)*100 -> 107400 | U54: =ROUND((U20)/100,U$66)*100 -> 79100 | V54: =ROUND((V20)/100,V$66)*100 -> 61700 | W54: =ROUND((W20)/100,W$66)*100 -> 53700 | X54: =ROUND((X20)/100,X$66)*100 -> 48200 | Y54: =ROUND((Y20)/100,Y$66)*100 -> 34000 | Z54: =ROUND((Z20)/100,Z$66)*100 -> 34100 | AA54: =ROUND((AA20)/100,AA$66)*100 -> 34900 | ... BC54: =ROUND((BC20)/100,BC$66)*100 -> 11800
A55: Special petroleum tax (adjusted for repayments) | I55: =I21+I23 -> 91513 | J55: =J21+J23 -> 50381 | K55: =K21+K23 -> 30189 | L55: =L21+L23 -> 58673.482 | M55: =M21+M23 -> 101113 | N55: =N21+N23 -> 81231.442 | O55: =O21+O23 -> -30264.474 | P55: =P21+P23 -> 192479.94 | ... S55: =S21+S23 -> 260874.97 | T55: =ROUND((T21+T22+T23+T43)/100,T$66)*100 -> 219500 | U55: =ROUND((U21+U22+U23+U43)/100,U$66)*100 -> 176600 | V55: =ROUND((V21+V22+V23+V43)/100,V$66)*100 -> 160800 | W55: =ROUND((W21+W22+W23+W43)/100,W$66)*100 -> 156800 | X55: =ROUND((X21+X22+X23)/100,X$66)*100 -> 142900 | Y55: =ROUND((Y21+Y22+Y23)/100,Y$66)*100 -> 99400 | Z55: =ROUND((Z21+Z22+Z23)/100,Z$66)*100 -> 104100 | AA55: =ROUND((AA21+AA22+AA23)/100,AA$66)*100 -> 104000 | AB55: =ROUND((AB21+AB22+AB23)/100,AB$66)*100 -> 99400 | AC55: =ROUND((AC21+AC22+AC23)/100,AC$66)*100 -> 107400 | AD55: =ROUND((AD21+AD22+AD23)/100,AD$66)*100 -> 113600 | AE55: =ROUND((AE21+AE22+AE23)/100,AE$66)*100 -> 115500 | ... BC55: =ROUND((BC21+BC22+BC23)/100,BC$66)*100 -> 39900
...

Sheet Petoro
A1: Data SDØE - rapportert fra Olje- og energidepartementet
A3: (Ikke avrundede tall)
A4: Kap. 2441 | B4: Teknologiutv. | C4: 1997 | D4: 1998 | E4: 1999 | F4: 2000 | G4: 2001 | H4: 2002 | I4: 2003 | J4: 2004 | K4: 2005 | L4: 2006 | M4: 2007 | N4: 2008 | O4: 2009 | P4: 2010 | Q4: 2011 | R4: 2012 | S4: 2013 | T4: 2014 | U4: 2015 | V4: 2016 | W4: 2017 | X4: 2018 | Y4: 2019 | Z4: 2020 | AA4: 2021 | AB4: 2022 | AC4: 2023 | AD4: 2024 | AE4: 2025 | AF4: 2026 | AG4: 2027 | AH4: 2028 | AI4: 2029 | AJ4: 2030 | AK4: 2031 | AL4: 2032 | AM4: 2033 | AN4: 2034 | AO4: 2035 | AP4: 2036 | AQ4: 2037 | AR4: 2038 | AS4: 2039 | AT4: 2040 | AU4: 2041 | AV4: 2042 | AW4: 2043 | AX4: 2044 | AY4: 2045 | AZ4: 2046 | BA4: 2047 | BB4: 2048 | BC4: 2049 | BD4: 2050 | BE4: 2051 | BF4: 2052 | BG4: 2053 | BH4: 2054 | BI4: 2055 | BJ4: 2056 | BK4: 2057 | BL4: 2058 | BM4: 2059 | BN4: 2060
A5: Post 50 | B5: Prosj. rettet tekn. utv. | C5: 0.258 | D5: 0 | E5: 0 | F5: 0
A6: Sum kap 2441 | C6: =C5 -> 0.258 | D6: =D5 -> 0 | E6: =E5 -> 0 | F6: =F5 -> 0 | G6: =G5 -> 0 | H6: =H5 -> 0 | I6: =I5 -> 0 | J6: =J5 -> 0 | ... BN6: =BN5 -> 0
A8: Kap. 2442 | B8: Disponering
A9: Post 21 | B9: Spes. dr. utg. | C9: 0.258 | D9: 1.766613 | E9: 3.493977 | F9: 3 | G9: 0 | H9: 0 | P9: 81.5 | Q9: 2 | R9: 0.027193 | S9: 0.62214487 | T9: 2 | U9: 0 | V9: 0 | W9: 0
A10: Post 70 | B10: Tilskudd | C10: 93.471 | D10: 69.887841 | E10: 15.374209 | F10: 0 | G10: 5.962 | H10: 47.715 | I10: 113.492 | J10: 125.261 | K10: 14.177 | L10: 0 | M10: 0 | N10: 0 | O10: 0 | P10: 0 | Q10: 0 | R10: 0 | S10: 0 | T10: 0 | U10: 0 | V10: 0 | W10: 0 | X10: 0 | Y10: 0 | Z10: 0 | AA10: 0 | AB10: 0 | AC10: 0 | AD10: 0 | AE10: 0 | AF10: 0 | AG10: 0 | AH10: 0 | AI10: 0 | AJ10: 0 | AK10: 0 | AL10: 0 | AM10: 0 | AN10: 0 | AO10: 0 | AP10: 0 | AQ10: 0 | AR10: 0 | AS10: 0 | AT10: 0 | AU10: 0 | AV10: 0 | AW10: 0 | AX10: 0 | AY10: 0 | AZ10: 0 | BA10: 0 | BB10: 0 | BC10: 0 | BD10: 0 | BE10: 0 | BF10: 0 | BG10: 0 | BH10: 0 | BI10: 0 | BJ10: 0 | BK10: 0 | BL10: 0 | BM10: 0 | BN10: 0
A11: Sum kap 2442 | C11: =C9+C10 -> 93.729 | D11: =D9+D10 -> 71.654454 | E11: =E9+E10 -> 18.868186 | F11: =F9+F10 -> 3 | G11: =G9+G10 -> 5.962 | H11: =H9+H10 -> 47.715 | I11: =I9+I10 -> 113.492 | J11: =J9+J10 -> 125.261 | ... BN11: =BN9+BN10 -> 0
A13: Kap. 2443 | B13: Petoro AS
A14: Post 70 | B14: Administrasjon | C14: 0.258 | D14: 0 | E14: 5.3 | F14: 0 | G14: 50 | H14: 250 | I14: 220 | J14: 0 | K14: =J14*(1+KVARTS!$H$12/100) -> 0 | L14: =K14*(1+KVARTS!$H$12/100) -> 0 | M14: =L14*(1+KVARTS!$H$12/100) -> 0 | N14: =M14*(1+KVARTS!$H$12/100) -> 0 | O14: =N14*(1+KVARTS!$H$12/100) -> 0 | P14: =O14*(1+KVARTS!$H$12/100) -> 0 | Q14: =P14*(1+KVARTS!$H$12/100) -> 0 | R14: =Q14*(1+KVARTS!$H$12/100) -> 0 | ... BN14: =BM14*(1+KVARTS!$H$12/100) -> 0
A15: Sum kap 2443 | C15: =C14 -> 0.258 | D15: =D14 -> 0 | E15: =E14 -> 5.3 | F15: =F14 -> 0 | G15: =G14 -> 50 | H15: =H14 -> 250 | I15: =I14 -> 220 | J15: =J14 -> 0 | ... BN15: =BN14 -> 0
A17: Kap. 5442 | B17: Disp. innretninger
A18: Post 80 | B18: Tilbakef. av tilskudd | C18: 0.258 | D18: 0 | E18: 5.316 | F18: 0 | G18: 0 | J18: 1.955
A19: Sum kap 5442 | C19: =C18 -> 0.258 | D19: =D18 -> 0 | E19: =E18 -> 5.316 | F19: =F18 -> 0 | G19: =G18 -> 0 | H19: =H18 -> 0 | I19: =I18 -> 0 | J19: =J18 -> 1.955 | ... BN19: =BN18 -> 0
A23: FBU+FUV
A24: Kap. 2440 | B24: SDØE
A25: Post 22 | B25: Fjerningsutg. | C25: 0 | D25: 0 | E25: 20.001241 | F25: 7.840046 | G25: 0 | H25: 86.578 | I25: 2.875 | J25: -0.015
A26: Post 25 | B26: Pro & contra oppgjør | G26: 8448.989 | H26: 1977.575 | I26: 208.905 | J26: 98.462248 | K26: 0.686004 | L26: 15.877961
A27: Post 30 | B27: Inv. | C27: 20341.944 | D27: 27250.755 | E27: 30336.998 | F27: 22647.354 | G27: 16569.099 | H27: 12807.833 | I27: 16038.211 | J27: 17323.845 | K27: 20701.299 | L27: 19967.276 | M27: 19950.561 | N27: 19997.732 | O27: 23596.66 | P27: 18470 | Q27: 21436.794 | R27: 25610.149 | S27: 33584.653 | T27: 35371 | U27: 29254.281 | V27: 27815.084 | W27: 26564.055 | X27: 22554.906 | Y27: 26330.658 | Z27: 27601 | AA27: 24732 | AB27: 28378 | AC27: 30396 | AD27: 35397 | AE27: 33400 | AF27: 36100 | AG27: 39600 | AH27: 39500 | AI27: 38600 | AJ27: 35048.05 | AK27: 32360.927 | AL27: 32650.254 | AM27: 30847.499 | AN27: 28551.896 | AO27: 24528.448 | AP27: 23302.028 | AQ27: 23380.023 | AR27: 23438.618 | AS27: 23397.07 | AT27: 22719.652 | AU27: 22315.609 | AV27: 20571.908 | AW27: 20636.644 | AX27: 20451.345 | AY27: 19310.67 | AZ27: 18982.422 | BA27: 18230.886 | BB27: 17821.604 | BC27: 17459.919 | BD27: 17065.078 | BE27: 16750.289 | BF27: 16322.349 | BG27: 15931.369 | BH27: 15764.283 | BI27: 15405.506 | BJ27: 14895.096 | BK27: 14420.287 | BL27: 13970.175 | BM27: 13528.569 | BN27: 13319.757
A28: Post 31 | B28: Kjøp av andelar | AD28: 13129 | AE28: -2046.441
A29: Post 50 | B29: Til p.f.fond | C29: 600 | D29: 285.984 | E29: 586 | F29: 592 | G29: =592 -> 592 | H29: 905 | I29: 980.6 | J29: 1113 | K29: 731 | L29: 1199 | M29: 1101 | N29: 1841 | O29: 1122 | P29: 1594 | Q29: 0 | R29: 0 | S29: 0 | T29: 0 | U29: 0 | V29: 0 | W29: 0 | X29: 0 | Y29: 0 | Z29: 0 | AA29: 0 | AB29: 0 | AC29: 0 | AD29: 0 | AE29: 0 | AF29: 0 | AG29: 0 | AH29: 0 | AI29: 0 | AJ29: 0 | AK29: 0 | AL29: 0 | AM29: 0 | AN29: 0 | AO29: 0 | AP29: 0 | AQ29: 0 | AR29: 0 | AS29: 0 | AT29: 0 | AU29: 0 | AV29: 0 | AW29: 0 | AX29: 0 | AY29: 0 | AZ29: 0 | BA29: 0 | BB29: 0 | BC29: 0 | BD29: 0 | BE29: 0 | BF29: 0 | BG29: 0 | BH29: 0 | BI29: 0 | BJ29: 0 | BK29: 0 | BL29: 0 | BM29: 0 | BN29: 0
A30: Sum Kap. 2440 | C30: =SUM(C25:C29) -> 20941.944 | D30: =SUM(D25:D29) -> 27536.739 | E30: =SUM(E25:E29) -> 30942.999 | F30: =SUM(F25:F29) -> 23247.195 | G30: =SUM(G25:G29) -> 25610.088 | H30: =SUM(H25:H29) -> 15776.986 | I30: =SUM(I25:I29) -> 17230.591 | J30: =SUM(J25:J29) -> 18535.292 | ... BN30: =SUM(BN25:BN29) -> 13319.757
A32: Kap. 5440 | B32: SDØE
A33: 01 | B33: Pro & contra oppgjør | H33: 347.881 | I33: 51.006 | J33: 118.98633 | K33: 233.073
A34: 24.01 | B34: Driftsinnt. | C34: 76899.51 | D34: 60262.914 | E34: 74581.097 | F34: 142264.77 | G34: 128589.42 | H34: 99935.367 | I34: 101184.7 | J34: 120331.7 | K34: 144181.51 | L34: 176443.19 | M34: 162924.99 | N34: 216722.17 | O34: 156123.52 | P34: 156745.94 | Q34: 183982.11 | R34: 213166.28 | S34: 197639.91 | T34: 185514 | U34: 158512.8 | V34: 127908.6 | W34: 145043.04 | X34: 175454.21 | Y34: 155059.3 | Z34: 113793.97 | AA34: 249674.3 | AB34: 634025.31 | AC34: 363492.33 | AD34: 313874 | AE34: 318700 | AF34: 274200 | AG34: 229300 | AH34: 219800 | AI34: 201100 | AJ34: 171905.25 | AK34: 163056.49 | AL34: 158113.64 | AM34: 154788.14 | AN34: 153597.5 | AO34: 148878.39 | AP34: 143381.39 | AQ34: 139496.81 | AR34: 132433.22 | AS34: 124366.15 | AT34: 118857.91 | AU34: 110263.41 | AV34: 110983.31 | AW34: 107681.55 | AX34: 104287 | AY34: 100931.62 | AZ34: 97694.897 | BA34: 94342.061 | BB34: 91099.772 | BC34: 86722.044 | BD34: 79477.73 | BE34: 76662.145 | BF34: 73824.363 | BG34: 70277.54 | BH34: 67712.022 | BI34: 66157.813 | BJ34: 62891.003 | BK34: 62182.572 | BL34: 61313.045 | BM34: 60387.93 | BN34: 60253.732
A35: 24.02 | B35: Driftsutg. | C35: -13473 | D35: -15563.819 | E35: -16849.842 | F35: -19584.97 | G35: -16765.714 | H35: -17763.887 | I35: -17362.291 | J35: -21696.296 | K35: -24289.046 | L35: -29077.688 | M35: -30350.799 | N35: -39869.835 | O35: -33709.84 | P35: -32477.388 | Q35: -32764.717 | R35: -36808.814 | S35: -36559.772 | T35: -34665 | U35: -34601.627 | V35: -31160.202 | W35: -28774.709 | X35: -32036.103 | Y35: -29995.982 | Z35: -28063.437 | AA35: -38308.416 | AB35: -74657.536 | AC35: -55109.741 | AD35: -43198.659 | AE35: -43200 | AF35: -43000 | AG35: -41500 | AH35: -41700 | AI35: -46100 | AJ35: -44881.815 | AK35: -45071.269 | AL35: -45394.803 | AM35: -44740.963 | AN35: -46336.245 | AO35: -45599.64 | AP35: -45920.683 | AQ35: -44880.826 | AR35: -46756.72 | AS35: -47595.268 | AT35: -48189.831 | AU35: -46779.257 | AV35: -46497.804 | AW35: -49682.279 | AX35: -45946.176 | AY35: -47587.088 | AZ35: -45603.835 | BA35: -46868.134 | BB35: -45036.947 | BC35: -43358.653 | BD35: -40745.753 | BE35: -40977.829 | BF35: -39644.165 | BG35: -40052.734 | BH35: -39801.142 | BI35: -38910.991 | BJ35: -35510.008 | BK35: -36096.649 | BL35: -32374.282 | BM35: -32546.957 | BN35: -32542.794
A36: 24.03 | B36: Leteutg. | C36: -2331.463 | D36: -2726.163 | E36: -1516.1244 | F36: -1879.4917 | G36: -1538.855 | H36: -1011.696 | I36: -642.541 | J36: -543.359 | K36: -978.364 | L36: -1122.226 | M36: -1423.993 | N36: -1962.8019 | O36: -2391.12 | P36: -1764.538 | Q36: -2005.3135 | R36: -1858.0599 | S36: -3199.8096 | T36: -2619.0849 | U36: -1940.4115 | V36: -2478.0089 | W36: -1432.2438 | X36: -2175.5065 | Y36: -2245.0205 | Z36: -1742.839 | AA36: -1463.8162 | AB36: -1955.951 | AC36: -1476.141 | AD36: -2907.356 | AE36: -2100 | AF36: -2100 | AG36: -1800 | AH36: -1800 | AI36: -1800 | AJ36: -2771.7101 | AK36: -2854.6718 | AL36: -2838.3866 | AM36: -2842.1338 | AN36: -2879.755 | AO36: -2887.6152 | AP36: -2890.2315 | AQ36: -2889.8383 | AR36: -2892.0349 | AS36: -2809.1141 | AT36: -2778.5878 | AU36: -2833.7854 | AV36: -2890.2066 | AW36: -2855.9949 | AX36: -2850.6323 | AY36: -2907.6449 | AZ36: -2965.7978 | BA36: -2925.3724 | BB36: -2983.8798 | BC36: -3043.5574 | BD36: -2998.5822 | BE36: -2878.6658 | BF36: -2936.2391 | BG36: -2994.9639 | BH36: -3054.8632 | BI36: -3115.9604 | BJ36: -3178.2796 | BK36: -3241.8452 | BL36: -3306.6821 | BM36: -3372.8158 | BN36: -3440.2721
A37: 24.04 | B37: Avskrivn. | C37: -14092.148 | D37: -14443.221 | E37: -15343.33 | F37: -17006.37 | G37: -17892.241 | H37: -14571.337 | I37: -14092.013 | J37: -14609.777 | K37: -12914.084 | L37: -14537.729 | M37: -15403.963 | N37: -15741.102 | O37: -15268.079 | P37: -15719.89 | Q37: -16861.847 | R37: -19500.976 | S37: -20261.842 | T37: -21837 | U37: -23721.755 | V37: -23276.648 | W37: -24648.044 | X37: -23636.285 | Y37: -22673.976 | Z37: -22438.631 | AA37: -25633.967 | AB37: -26314.13 | AC37: -27206.412 | AD37: 29599.681 | AE37: -33500 | AF37: -39300 | AG37: -40000 | AH37: -45700 | AI37: -32300
A38: 24.05 | B38: Renter | C38: -8983.521 | D38: -8535.8508 | E38: -8419.9428 | F38: -8397.8829 | G38: -7487.597 | H38: -6362.82 | I38: -6392.093 | J38: -6677.383 | K38: -6670.289 | L38: -6844.4532 | M38: -6929.15 | N38: -6572.8041 | O38: -6469 | P38: -6526.391 | Q38: -6529.898 | R38: -6552.8533 | S38: -6014.3654 | T38: -4944 | U38: -4104.0022 | V38: -3805.8039 | W38: -3567.9702 | X38: -3096.414 | Y38: -2768.2806 | Z38: -2474.387 | AA38: -2331.3975 | AB38: -2377.552 | AC38: -2696.659 | AD38: -4015.564 | AE38: -5000 | AF38: -5000 | AG38: -6900 | AH38: -8300 | AI38: -9300
A39: SUM 24 | B39: Driftsresultat | C39: =SUM(C34:C38) -> 38019.378 | D39: =SUM(D34:D38) -> 18993.86 | E39: =SUM(E34:E38) -> 32451.859 | F39: =SUM(F34:F38) -> 95396.056 | G39: =SUM(G34:G38) -> 84905.014 | H39: =SUM(H34:H38) -> 60225.627 | I39: =SUM(I34:I38) -> 62695.761 | J39: =SUM(J34:J38) -> 76804.886 | ... BN39: =SUM(BN34:BN38) -> 24270.666
A40: Post 30 | B40: Avskrivn. | C40: =-C37 -> 14092.148 | D40: =-D37 -> 14443.221 | E40: =-E37 -> 15343.33 | F40: =-F37 -> 17006.37 | G40: =-G37 -> 17892.241 | H40: =-H37 -> 14571.337 | I40: =-I37 -> 14092.013 | J40: =-J37 -> 14609.777 | ... BN40: =-BN37 -> 0
A41: Post 31 | B41: Salg andeler | G41: =38979.889 -> 38979.889 | H41: 8521
A42: Post 50 | B42: Fra p.f.fond | C42: 118.084 | D42: 182.29755 | E42: 517.0861 | F42: 652.57364 | G42: 565.862 | H42: 284.885 | I42: 1482.152 | J42: 490.36801 | K42: 887.569 | L42: 462.18282 | M42: 1136.551 | N42: 707.82981 | O42: 35 | P42: 737.849
A43: Post 80 | B43: Renter av statens kapital (Renter fast kapital) | C43: =-C38 -> 8983.521 | D43: =-D38 -> 8535.8508 | E43: =-E38 -> 8419.9428 | F43: =-F38 -> 8397.8829 | G43: =-G38 -> 7487.597 | H43: =-H38 -> 6362.82 | I43: 6390.077 | J43: 6666.301 | K43: 6646.122 | L43: 6820.1768 | M43: 6918.46 | N43: 6559.904 | O43: 6456 | P43: 6527.677 | Q43: 6540.51 | R43: 6574.6875 | S43: 6041.2852 | T43: 4968 | U43: 4127.036 | V43: 3819.8187 | W43: 3580.822 | X43: 3113.578 | Y43: 2791.025 | Z43: 2483.311 | AA43: 2331.386 | AB43: 2382.093 | AC43: 2707.84 | AD43: 4026.08 | AE43: 5000 | AF43: 5000 | AG43: 6900 | AH43: 8300 | AI43: 9300 | AJ43: =-AJ38 -> 0 | AK43: =-AK38 -> 0 | AL43: =-AL38 -> 0 | AM43: =-AM38 -> 0 | AN43: =-AN38 -> 0 | AO43: =-AO38 -> 0 | AP43: =-AP38 -> 0 | AQ43: =-AQ38 -> 0 | ... BN43: =-BN38 -> 0
A44: Post 81 | B44: Renter, salg av SDØE-andeler | G44: 1247.806 | H44: 248.773
A45: Post 85 | B45: Renter på mellomregnskapet | C45: 132.085 | D45: -46.554115 | E45: -19.79787 | F45: 13.007133 | G45: =-29.229 -> -29.229 | I45: 2.016 | J45: 11.081 | K45: 24.167 | L45: 24.276424 | M45: 10.69 | N45: 12.319158 | O45: 13 | P45: -1.2863051 | Q45: -10.672243 | R45: -21.834221 | S45: -26.919735 | T45: -23 | U45: 0 | V45: -14.014774 | W45: -12.852 | X45: -17.164 | Y45: -31.793 | Z45: -8.9242093 | AA45: 0.012 | AB45: -5.351 | AC45: -11.181 | AD45: -10.516 | AE45: 0 | AF45: 0 | AG45: 0 | AH45: 0 | AI45: 0
A46: Post 84 | B46: E. oppgjør
P47: 875
A48: Sum Kap. 5440 | C48: =SUM(C39:C46) -> 61345.216 | D48: =SUM(D39:D46) -> 42108.675 | E48: =SUM(E39:E46) -> 56712.419 | F48: =SUM(F39:F46) -> 121465.89 | G48: =SUM(G39:G46) -> 151049.18 | H48: =SUM(H39:H46)+H33 -> 90562.323 | I48: =SUM(I39:I46)+I33 -> 84713.025 | J48: =SUM(J39:J46)+J33 -> 98701.399 | K48: =SUM(K39:K46)+K33 -> 120034.75 | L48: =SUM(L39:L46) -> 146705.46 | M48: =SUM(M39:M46) -> 132286.75 | N48: =SUM(N39:N47) -> 175596.78 | O48: =SUM(O39:O47) -> 120057.56 | P48: =SUM(P39:P47) -> 124116.86 | Q48: =SUM(Q39:Q46) -> 149212.02 | R48: =SUM(R39:R46) -> 174499.4 | S48: =SUM(S39:S46) -> 157880.33 | T48: =SUM(T39:T46) -> 148230.92 | U48: =SUM(U39:U46) -> 121993.79 | V48: =SUM(V39:V46) -> 94270.392 | W48: =SUM(W39:W46) -> 114836.09 | X48: =SUM(X39:X46) -> 141242.6 | ... BN48: =SUM(BN39:BN46) -> 24270.666
...

Sheet Formue
B1: 2000 | C1: 2001 | D1: 2002 | E1: 2003 | F1: 2004 | G1: 2005 | H1: 2006 | I1: 2007 | J1: 2008 | K1: 2009 | L1: 2010 | M1: 2011 | N1: 2012 | O1: 2013 | P1: 2014 | Q1: 2015 | R1: 2016 | S1: 2017 | T1: 2018 | U1: 2019 | V1: 2020 | W1: 2021 | X1: 2022 | Y1: 2023 | Z1: 2024 | AA1: 2025 | AB1: 2026 | AC1: 2027 | AD1: 2028 | AE1: 2029 | AF1: 2030 | AG1: 2031 | AH1: 2032 | AI1: 2033 | AJ1: 2034 | AK1: 2035 | AL1: 2036 | AM1: 2037 | AN1: 2038 | AO1: 2039 | AP1: 2040 | AQ1: 2041 | AR1: 2042 | AS1: 2043 | AT1: 2044 | AU1: 2045 | AV1: 2046 | AW1: 2047 | AX1: 2048 | AY1: 2049 | AZ1: 2050 | BA1: 2051 | BB1: 2052 | BC1: 2053 | BD1: 2054 | BE1: 2055 | BF1: 2056 | BG1: 2057 | BH1: 2058 | BI1: 2059 | BJ1: 2060 | BK1: 2061 | BL1: 2062 | BM1: 2063 | BN1: 2064 | BO1: 2065 | BP1: 2066 | BQ1: 2067 | BR1: 2068 | BS1: 2069 | BT1: 2070 | BU1: 2071 | BV1: 2072 | BW1: 2073 | BX1: 2074 | BY1: 2075 | BZ1: 2076 | CA1: 2077 | CB1: 2078 | CC1: 2079 | CD1: 2080 | CE1: 2081 | CF1: 2082 | CG1: 2083 | CH1: 2084 | CI1: 2085 | CJ1: 2086 | CK1: 2087 | CL1: 2088 | CM1: 2089 | CN1: 2090
H3: 2031-2050 | J3: 2036-2050 | L3: 2040-2050 | N3: Faktor som anvendes
A4: Vekstrater | B4: 2031-2050 | C4: 2051-2090 | F4: Totalproduksjon | H4: =(AZ34/AG34)^(1/20) -> 0.96246528 | J4: =(AZ34/AL34)^(1/20) -> 0.9701335 | L4: =(AZ34/AQ34)^(1/20) -> 0.98213128
A6: Prisvekst | F6: Påløpte driftsutgifter (faste) | H6: =(AZ54/AG54)^(1/20) -> 0.98238415 | J6: =(AZ54/AL54)^(1/20) -> 0.98472439 | L6: =(AZ54/AQ54)^(1/20) -> 0.98968385
F7: Faktor | H7: =H6/H4 -> 1.0206957 | J7: =J6/J4 -> 1.0150401 | L7: =L6/L4 -> 1.00769 | N7: 1.016 | P7: Samme faktor i NB20 og RNB20
A8: Oljeproduksjon mill. Sm3 oe | B8: -335544.32 | C8: 0.023767071
A9: Gassproduksjon mill. Sm3 oe | C9: 0.008938545 | F9: Investeringsutgifter, faste priser | H9: =(AZ57/AG57)^(1/20) -> 0.97505411 | J9: =(AZ57/AL57)^(1/20) -> 0.98471592 | L9: =(AZ57/AQ57)^(1/20) -> 0.98800527
A10: NGL-produksjon mill. Sm3 oe | C10: 1.1885227 | F10: Faktor | H10: =H9/H4 -> 1.0130798 | J10: =J9/J4 -> 1.0150314 | L10: =L9/L4 -> 1.0059809 | N10: 1.005 | P10: Samme faktor i NB20 og RNB20
A12: Påløpte driftsutgifter | C12: -0.01
A13: Påløpte fjerningsutgifter | C13: 0.03
A14: Påløpte investeringsutgifter | C14: -0.05
A16: Startverdi 2031 | C16: 0.9
B19: Produksjon | C19: ODs anslag | D19: Andel av | E19: Gjenværende
B20: i beregnings- | C20: på gjenværende | D20: ressursene | E20: ressurser
B21: perioden | C21: ressurser | D21: som blir
C22: pr. 31.12.2022 | D22: produsert
A23: Samlet oljeproduksjon | B23: =SUM(Y30:CN30) -> 3120.7826 | C23: 3520 | D23: =B23/C23 -> 0.88658598 | E23: =C23-B23 -> 399.21735
A24: Samlet gassproduksjon | B24: =SUM(Y31:CN31) -> 3587.8259 | C24: 3684 | D24: =B24/C24 -> 0.97389412 | E24: =C24-B24 -> 96.174062
A25: Samlet NGL-produksjon | B25: =SUM(Y32:CN32) -> 227.4449 | C25: 316 | D25: =B25/C25 -> 0.71976235 | E25: =C25-B25 -> 88.555098
A26: Samlet | B26: =SUM(B23:B25) -> 6936.0535 | C26: =SUM(C23:C25) -> 7520 | D26: =B26/C26 -> 0.92234754 | E26: =C26-B26 -> 583.94651
A27: Formlene oppdatert
A29: Produksjon Mill. Sm3
A30: Produksjon av råolje | I30: =KVARTS!L62 -> 128.28 | J30: =KVARTS!M62 -> 122.66 | K30: =KVARTS!N62 -> 114.94 | L30: =KVARTS!O62 -> 104.39 | M30: =KVARTS!P62 -> 97.46 | N30: =KVARTS!Q62 -> 89.2 | O30: =KVARTS!R62 -> 84.94 | P30: =KVARTS!S62 -> 87.7 | ... BJ30: =KVARTS!BM62 -> 28.071747 | BK30: =BJ30 -> 28.071747 | BL30: =BK30 -> 28.071747 | BM30: =BL30 -> 28.071747 | BN30: =BM30 -> 28.071747 | BO30: =BN30 -> 28.071747 | BP30: =BO30 -> 28.071747 | BQ30: =BP30 -> 28.071747 | BR30: =BQ30 -> 28.071747 | ... CN30: =CM30 -> 28.071747
A31: Produksjon av naturgass | I31: =KVARTS!L63 -> 89.51 | J31: =KVARTS!M63 -> 99.46 | K31: =KVARTS!N63 -> 103.68 | L31: =KVARTS!O63 -> 106.53 | M31: =KVARTS!P63 -> 100.3 | N31: =KVARTS!Q63 -> 113.06 | O31: =KVARTS!R63 -> 107.05 | P31: =KVARTS!S63 -> 106.8 | ... BJ31: =KVARTS!BM63 -> 32.602377 | BK31: =BJ31 -> 32.602377 | BL31: =BK31 -> 32.602377 | BM31: =BL31 -> 32.602377 | BN31: =BM31 -> 32.602377 | BO31: =BN31 -> 32.602377 | BP31: =BO31 -> 32.602377 | BQ31: =BP31 -> 32.602377 | BR31: =BQ31 -> 32.602377 | ... CN31: =CM31 -> 32.602377
A32: Produksjon av NGL | I32: =KVARTS!L64 -> 19.76 | J32: =KVARTS!M64 -> 20.86 | K32: =KVARTS!N64 -> 21.4 | L32: =KVARTS!O64 -> 19.72 | M32: =KVARTS!P64 -> 20.89 | N32: =KVARTS!Q64 -> 22.38 | O32: =KVARTS!R64 -> 21.71 | P32: =KVARTS!S64 -> 21.86 | ... BJ32: =KVARTS!BM64 -> 0.046981571 | BK32: =BJ32 -> 0.046981571 | BL32: =BK32 -> 0.046981571 | BM32: =BL32 -> 0.046981571 | BN32: =BM32 -> 0.046981571 | BO32: =BN32 -> 0.046981571 | BP32: =BO32 -> 0.046981571 | BQ32: =BP32 -> 0.046981571 | BR32: =BQ32 -> 0.046981571 | ... CN32: =CM32 -> 0.046981571
A33: Råolje og NGL | I33: =I30+I32 -> 148.04 | J33: =J30+J32 -> 143.52 | K33: =K30+K32 -> 136.34 | L33: =L30+L32 -> 124.11 | M33: =M30+M32 -> 118.35 | N33: =N30+N32 -> 111.58 | O33: =O30+O32 -> 106.65 | P33: =P30+P32 -> 109.56 | ... CN33: =CN30+CN32 -> 28.118729
A34: Total produksjon | I34: =I30+I31+I32 -> 237.55 | J34: =J30+J31+J32 -> 242.98 | K34: =K30+K31+K32 -> 240.02 | L34: =L30+L31+L32 -> 230.64 | M34: =M30+M31+M32 -> 218.65 | N34: =N30+N31+N32 -> 224.64 | O34: =O30+O31+O32 -> 213.7 | P34: =P30+P31+P32 -> 216.36 | ... CN34: =CN30+CN31+CN32 -> 60.721106
A37: Priser
A38: Oljepris NOK/Sm3 o.e. | I38: =KVARTS!L33*(1+Skiftberegning!H25) -> 2673.1692 | J38: =KVARTS!M33*(1+Skiftberegning!I25) -> 3497.1344 | K38: =KVARTS!N33*(1+Skiftberegning!J25) -> 2459.3157 | L38: =KVARTS!O33*(1+Skiftberegning!K25) -> 3050.5579 | M38: =KVARTS!P33*(1+Skiftberegning!L25) -> 3912.2618 | N38: =KVARTS!Q33*(1+Skiftberegning!M25) -> 4088.3765 | O38: =KVARTS!R33*(1+Skiftberegning!N25) -> 4019.1886 | P38: =KVARTS!S33*(1+Skiftberegning!O25) -> 3943.7109 | ... BJ38: =KVARTS!BM33*(1+Skiftberegning!BI25) -> 8809.834 | BK38: =Skiftberegning!BJ2*Skiftberegning!BJ15*(1+Skiftberegning!BJ25) -> 8986.0307 | BL38: =Skiftberegning!BK2*Skiftberegning!BK15*(1+Skiftberegning!BK25) -> 9165.7513 | BM38: =Skiftberegning!BL2*Skiftberegning!BL15*(1+Skiftberegning!BL25) -> 9349.0663 | BN38: =Skiftberegning!BM2*Skiftberegning!BM15*(1+Skiftberegning!BM25) -> 9536.0476 | BO38: =Skiftberegning!BN2*Skiftberegning!BN15*(1+Skiftberegning!BN25) -> 9726.7686 | BP38: =Skiftberegning!BO2*Skiftberegning!BO15*(1+Skiftberegning!BO25) -> 9921.3039 | BQ38: =Skiftberegning!BP2*Skiftberegning!BP15*(1+Skiftberegning!BP25) -> 10119.73 | BR38: =Skiftberegning!BQ2*Skiftberegning!BQ15*(1+Skiftberegning!BQ25) -> 10322.125 | ... CN38: =Skiftberegning!CM2*Skiftberegning!CM15*(1+Skiftberegning!CM25) -> 15957.795
A39: Gasspris NOK/Sm3 o.e. | I39: =KVARTS!L34*(1+Skiftberegning!H26) -> 1570 | J39: =KVARTS!M34*(1+Skiftberegning!I26) -> 2220 | K39: =KVARTS!N34*(1+Skiftberegning!J26) -> 1670 | L39: =KVARTS!O34*(1+Skiftberegning!K26) -> 1590 | M39: =KVARTS!P34*(1+Skiftberegning!L26) -> 2000 | N39: =KVARTS!Q34*(1+Skiftberegning!M26) -> 2210 | O39: =KVARTS!R34*(1+Skiftberegning!N26) -> 2310 | P39: =KVARTS!S34*(1+Skiftberegning!O26) -> 2050 | ... BJ39: =KVARTS!BM34*(1+Skiftberegning!BI26) -> 4310.7792 | BK39: =Skiftberegning!BJ5*Skiftberegning!BJ16*(1+Skiftberegning!BJ26) -> 4396.9948 | BL39: =Skiftberegning!BK5*Skiftberegning!BK16*(1+Skiftberegning!BK26) -> 4484.9347 | BM39: =Skiftberegning!BL5*Skiftberegning!BL16*(1+Skiftberegning!BL26) -> 4574.6334 | BN39: =Skiftberegning!BM5*Skiftberegning!BM16*(1+Skiftberegning!BM26) -> 4666.1261 | BO39: =Skiftberegning!BN5*Skiftberegning!BN16*(1+Skiftberegning!BN26) -> 4759.4486 | BP39: =Skiftberegning!BO5*Skiftberegning!BO16*(1+Skiftberegning!BO26) -> 4854.6376 | BQ39: =Skiftberegning!BP5*Skiftberegning!BP16*(1+Skiftberegning!BP26) -> 4951.7303 | BR39: =Skiftberegning!BQ5*Skiftberegning!BQ16*(1+Skiftberegning!BQ26) -> 5050.7649 | ... CN39: =Skiftberegning!CM5*Skiftberegning!CM16*(1+Skiftberegning!CM26) -> 7808.3799
A40: NGL-pris kr/Sm3 o.e. | I40: =KVARTS!L8*(1+Skiftberegning!H25) -> 1814.6526 | J40: =KVARTS!M8*(1+Skiftberegning!I25) -> 2521.0891 | K40: =KVARTS!N8*(1+Skiftberegning!J25) -> 1763.5173 | L40: =KVARTS!O8*(1+Skiftberegning!K25) -> 2199.1357 | M40: =KVARTS!P8*(1+Skiftberegning!L25) -> 2796 | N40: =KVARTS!Q8*(1+Skiftberegning!M25) -> 2896 | O40: =KVARTS!R8*(1+Skiftberegning!N25) -> 2814.8571 | P40: =KVARTS!S8*(1+Skiftberegning!O25) -> 2352.3148 | ... BJ40: =KVARTS!BM8*(1+Skiftberegning!BI25) -> 5111.4616 | BK40: =Skiftberegning!BJ6*(1+Skiftberegning!BJ25) -> 5213.6909 | BL40: =Skiftberegning!BK6*(1+Skiftberegning!BK25) -> 5317.9647 | BM40: =Skiftberegning!BL6*(1+Skiftberegning!BL25) -> 5424.324 | BN40: =Skiftberegning!BM6*(1+Skiftberegning!BM25) -> 5532.8104 | BO40: =Skiftberegning!BN6*(1+Skiftberegning!BN25) -> 5643.4667 | BP40: =Skiftberegning!BO6*(1+Skiftberegning!BO25) -> 5756.336 | BQ40: =Skiftberegning!BP6*(1+Skiftberegning!BP25) -> 5871.4627 | BR40: =Skiftberegning!BQ6*(1+Skiftberegning!BQ25) -> 5988.892 | ... CN40: =Skiftberegning!CM6*(1+Skiftberegning!CM25) -> 9258.7052
A41: Oljepris 2015-NOK pr. fat | I41: =KVARTS!L24 -> 686.78097 | J41: =KVARTS!M24 -> 865.25317 | K41: =KVARTS!N24 -> 610.64954 | L41: =KVARTS!O24 -> 745.23316 | M41: =KVARTS!P24 -> 926.49437 | N41: =KVARTS!Q24 -> 948.57235 | O41: =KVARTS!R24 -> 919.05694 | P41: =KVARTS!S24 -> 887.40201 | ... BJ41: =KVARTS!BM24 -> 712.27491 | BK41: =BJ41 -> 712.27491 | BL41: =BK41 -> 712.27491 | BM41: =BL41 -> 712.27491 | BN41: =BM41 -> 712.27491 | BO41: =BN41 -> 712.27491 | BP41: =BO41 -> 712.27491 | BQ41: =BP41 -> 712.27491 | BR41: =BQ41 -> 712.27491 | ... CN41: =CM41 -> 712.27491
A43: Prisvekst | B43: =KVARTS!E12 -> 3.3768573 | C43: =KVARTS!F12 -> 2.8261711 | D43: =KVARTS!G12 -> 1.5860316 | E43: =KVARTS!H12 -> 2.270095 | F43: =KVARTS!I12 -> 2.6772367 | G43: =KVARTS!J12 -> 3.3927468 | H43: =KVARTS!K12 -> 3.2259441 | I43: =KVARTS!L12 -> 2.8526725 | ... BJ43: =KVARTS!BM12 -> 2 | BK43: =BJ43 -> 2 | BL43: =BK43 -> 2 | BM43: =BL43 -> 2 | BN43: =BM43 -> 2 | BO43: =BN43 -> 2 | BP43: =BO43 -> 2 | BQ43: =BP43 -> 2 | BR43: =BQ43 -> 2 | ... CN43: =CM43 -> 2
A44: Deflator | B44: =KVARTS!E13 -> 0.51394384 | C44: =KVARTS!F13 -> 0.52846878 | D44: =KVARTS!G13 -> 0.53685046 | E44: =KVARTS!H13 -> 0.54903747 | F44: =KVARTS!I13 -> 0.56373651 | G44: =KVARTS!J13 -> 0.58286266 | H44: =KVARTS!K13 -> 0.60166548 | I44: =KVARTS!L13 -> 0.61882903 | ... BJ44: =KVARTS!BM13 -> 1.9664484 | BK44: =BJ44*(1+BK43/100) -> 2.0057773 | BL44: =BK44*(1+BL43/100) -> 2.0458929 | BM44: =BL44*(1+BM43/100) -> 2.0868108 | BN44: =BM44*(1+BN43/100) -> 2.128547 | BO44: =BN44*(1+BO43/100) -> 2.1711179 | BP44: =BO44*(1+BP43/100) -> 2.2145403 | BQ44: =BP44*(1+BQ43/100) -> 2.2588311 | BR44: =BQ44*(1+BR43/100) -> 2.3040077 | ... CN44: =CM44*(1+CN43/100) -> 3.5619491
A46: Markedsverdi Mill. kr
A47: Olje | I47: =KVARTS!L80+Skiftberegning!H55 -> 342914.15 | J47: =KVARTS!M80+Skiftberegning!I55 -> 428958.5 | K47: =KVARTS!N80+Skiftberegning!J55 -> 282673.75 | L47: =KVARTS!O80+Skiftberegning!K55 -> 318447.73 | M47: =KVARTS!P80+Skiftberegning!L55 -> 381289.04 | N47: =KVARTS!Q80+Skiftberegning!M55 -> 364683.18 | O47: =KVARTS!R80+Skiftberegning!N55 -> 341389.88 | P47: =KVARTS!S80+Skiftberegning!O55 -> 345863.44 | ... BJ47: =KVARTS!BM80+Skiftberegning!BI55 -> 247307.43 | BK47: =BK30*BK38 -> 252253.58 | BL47: =BL30*BL38 -> 257298.65 | BM47: =BM30*BM38 -> 262444.62 | BN47: =BN30*BN38 -> 267693.52 | BO47: =BO30*BO38 -> 273047.39 | BP47: =BP30*BP38 -> 278508.33 | BQ47: =BQ30*BQ38 -> 284078.5 | BR47: =BR30*BR38 -> 289760.07 | ... CN47: =CN30*CN38 -> 447963.18
A48: Gass | I48: =KVARTS!L81+Skiftberegning!H58 -> 140530.7 | J48: =KVARTS!M81+Skiftberegning!I58 -> 220801.2 | K48: =KVARTS!N81+Skiftberegning!J58 -> 173145.6 | L48: =KVARTS!O81+Skiftberegning!K58 -> 169382.7 | M48: =KVARTS!P81+Skiftberegning!L58 -> 200600 | N48: =KVARTS!Q81+Skiftberegning!M58 -> 249862.6 | O48: =KVARTS!R81+Skiftberegning!N58 -> 247285.5 | P48: =KVARTS!S81+Skiftberegning!O58 -> 218940 | ... BJ48: =KVARTS!BM81+Skiftberegning!BI58 -> 140541.65 | BK48: =BK31*BK39 -> 143352.48 | BL48: =BL31*BL39 -> 146219.53 | BM48: =BM31*BM39 -> 149143.92 | BN48: =BN31*BN39 -> 152126.8 | BO48: =BO31*BO39 -> 155169.34 | BP48: =BP31*BP39 -> 158272.73 | BQ48: =BQ31*BQ39 -> 161438.18 | BR48: =BR31*BR39 -> 164666.94 | ... CN48: =CN31*CN39 -> 254571.75
A49: NGL | I49: =KVARTS!L82+Skiftberegning!H56 -> 35857.535 | J49: =KVARTS!M82+Skiftberegning!I56 -> 52589.919 | K49: =KVARTS!N82+Skiftberegning!J56 -> 37739.27 | L49: =KVARTS!O82+Skiftberegning!K56 -> 43366.957 | M49: =KVARTS!P82+Skiftberegning!L56 -> 58408.44 | N49: =KVARTS!Q82+Skiftberegning!M56 -> 64812.48 | O49: =KVARTS!R82+Skiftberegning!N56 -> 61110.549 | P49: =KVARTS!S82+Skiftberegning!O56 -> 51421.602 | ... BJ49: =KVARTS!BM82+Skiftberegning!BI56 -> 240.1445 | BK49: =BK32*BK40 -> 244.94739 | BL49: =BL32*BL40 -> 249.84633 | BM49: =BM32*BM40 -> 254.84326 | BN49: =BN32*BN40 -> 259.94013 | BO49: =BO32*BO40 -> 265.13893 | BP49: =BP32*BP40 -> 270.44171 | BQ49: =BQ32*BQ40 -> 275.85054 | BR49: =BR32*BR40 -> 281.36755 | ... CN49: =CN32*CN40 -> 434.98852
A50: Sum | I50: =KVARTS!L83+Skiftberegning!H59 -> 519302.39 | J50: =KVARTS!M83+Skiftberegning!I59 -> 702349.62 | K50: =KVARTS!N83+Skiftberegning!J59 -> 493558.62 | L50: =KVARTS!O83+Skiftberegning!K59 -> 531197.39 | M50: =KVARTS!P83+Skiftberegning!L59 -> 640297.48 | N50: =KVARTS!Q83+Skiftberegning!M59 -> 679358.26 | O50: =KVARTS!R83+Skiftberegning!N59 -> 649785.93 | P50: =KVARTS!S83+Skiftberegning!O59 -> 616225.05 | ... BJ50: =KVARTS!BM83+Skiftberegning!BI59 -> 388089.23 | BK50: =SUM(BK47:BK49) -> 395851.01 | BL50: =SUM(BL47:BL49) -> 403768.03 | BM50: =SUM(BM47:BM49) -> 411843.39 | BN50: =SUM(BN47:BN49) -> 420080.26 | BO50: =SUM(BO47:BO49) -> 428481.86 | BP50: =SUM(BP47:BP49) -> 437051.5 | BQ50: =SUM(BQ47:BQ49) -> 445792.53 | BR50: =SUM(BR47:BR49) -> 454708.38 | ... CN50: =SUM(CN47:CN49) -> 702969.91
A53: Utgifter
...

Sheet FAME Persistence2
A1: 27 | B1: SNKS
A2: KVARTS | B2: $C$219 | C2: A1:AA1 | D2: 506539.09 | E2: 45737.457 | F2: TRUE | G2: rnb25a13'X6667 | H2: 1998 | I2: 2024 | J2: 0 | K2: Annual | L2: TRUE | M2: FALSE | N2: FALSE
A3: KVARTS | B3: $C$227 | C3: A1:AA1 | D3: 0.9578125 | E3: 45737.457 | F3: TRUE | G3: rnb25a13'PA69 | H3: 1998 | I3: 2024 | J3: 0 | K3: Annual | L3: TRUE | M3: FALSE | N3: FALSE
A4: KVARTS | B4: $C$220 | C4: A1:AA1 | D4: 13625.811 | E4: 45737.457 | F4: TRUE | G4: rnb25a13'X6682 | H4: 1998 | I4: 2024 | J4: 0 | K4: Annual | L4: TRUE | M4: FALSE | N4: FALSE
A5: KVARTS | B5: $C$230 | C5: A1:AA1 | D5: 32911 | E5: 45737.457 | F5: TRUE | G5: rnb25a13'vh66+rnb25a13'vh68 | H5: 1998 | I5: 2024 | J5: 0 | K5: Annual | L5: TRUE | M5: FALSE | N5: FALSE
A6: KVARTS | B6: $C$217 | C6: A1:AA1 | D6: 37762.196 | E6: 45737.457 | F6: TRUE | G6: rnb25a13'X6631 | H6: 1998 | I6: 2024 | J6: 0 | K6: Annual | L6: TRUE | M6: FALSE | N6: FALSE
A7: KVARTS | B7: $C$218 | C7: A1:AA1 | D7: 978645.62 | E7: 45737.457 | F7: TRUE | G7: rnb25a13'X6666 | H7: 1998 | I7: 2024 | J7: 0 | K7: Annual | L7: TRUE | M7: FALSE | N7: FALSE
A8: Investments | B8: $C$125 | C8: A1:AC1 | D8: 785.67907 | E8: 45867.527 | F8: TRUE | G8: nb26b11'jk5068 | H8: 1996 | I8: 2024 | J8: 0 | K8: Annual | L8: TRUE | M8: FALSE | N8: FALSE
A9: Investments | B9: $C$113 | C9: A1:AC1 | D9: 7317.7961 | E9: 45867.527 | F9: TRUE | G9: nb26b11'jk7166 | H9: 1996 | I9: 2024 | J9: 0 | K9: Annual | L9: TRUE | M9: FALSE | N9: FALSE
A10: Investments | B10: $C$108 | C10: A1:AC1 | D10: 20722.593 | E10: 45867.527 | F10: TRUE | G10: nb26b11'jk2266 | H10: 1996 | I10: 2024 | J10: 0 | K10: Annual | L10: TRUE | M10: FALSE | N10: FALSE
A11: Investments | B11: $C$112 | C11: A1:AC1 | D11: 14658.744 | E11: 45867.527 | F11: TRUE | G11: nb26b11'jk7266 | H11: 1996 | I11: 2024 | J11: 0 | K11: Annual | L11: TRUE | M11: FALSE | N11: FALSE
A12: Investments | B12: $C$124 | C12: A1:AC1 | D12: 2.9084491 | E12: 45867.527 | F12: TRUE | G12: nb26b11'jk4068 | H12: 1996 | I12: 2024 | J12: 0 | K12: Annual | L12: TRUE | M12: FALSE | N12: FALSE
A13: Investments | B13: $C$128 | C13: A1:AC1 | D13: 52.005162 | E13: 45867.527 | F13: TRUE | G13: nb26b11'jk6068 | H13: 1996 | I13: 2024 | J13: 0 | K13: Annual | L13: TRUE | M13: FALSE | N13: FALSE
... A28: Investments | B28: $C$115 | C28: A1:AC1 | D28: 16321.268 | E28: 45867.527 | F28: TRUE | G28: nb26b11'jk7466 | H28: 1996 | I28: 2024 | J28: 0 | K28: Annual | L28: TRUE | M28: FALSE | N28: FALSE

Sheet Charts
A1: Charts 1
A4: Oil price, fixed 2026-prices, USD/barrel | B4: Remark: If necessary you must adjust to the same price year with inflation forecast to the respective rounds
B5: 2023 | C5: 2024 | D5: 2025 | E5: 2026 | F5: 2027 | G5: 2028 | H5: 2029 | I5: 2030 | J5: 2031 | K5: 2032 | L5: 2033 | M5: 2034 | N5: 2035 | O5: 2036 | P5: 2037 | Q5: 2038 | R5: 2039 | S5: 2040 | T5: 2041 | U5: 2042 | V5: 2043 | W5: 2044 | X5: 2045 | Y5: 2046 | Z5: 2047 | AA5: 2048 | AB5: 2049 | AC5: 2050 | AD5: 2051 | AE5: 2052 | AF5: 2053 | AG5: 2054 | AH5: 2055 | AI5: 2056 | AJ5: 2057 | AK5: 2058 | AL5: 2059 | AM5: 2060 | AN5: 2061 | AO5: 2062 | AP5: 2063 | AQ5: 2064 | AR5: 2065 | AS5: 2066 | AT5: 2067 | AU5: 2068 | AV5: 2069 | AW5: 2070 | AX5: 2071 | AY5: 2072 | AZ5: 2073 | BA5: 2074 | BB5: 2075 | BC5: 2076 | BD5: 2077 | BE5: 2078 | BF5: 2079 | BG5: 2080 | BH5: 2081 | BI5: 2082 | BJ5: 2083 | BK5: 2084 | BL5: 2085 | BM5: 2086 | BN5: 2087 | BO5: 2088 | BP5: 2089 | BQ5: 2090
A6: NB26 | B6: =KVARTS!AB31 -> 90.251069 | C6: =KVARTS!AC31 -> 85.047828 | D6: =KVARTS!AD31 -> 71.7493 | E6: =KVARTS!AE31 -> 66.6925 | F6: =KVARTS!AF31 -> 65.269344 | G6: =KVARTS!AG31 -> 64.285812 | H6: =KVARTS!AH31 -> 63.252491 | I6: =KVARTS!AI31 -> 62.052929 | ... BQ6: =KVARTS!CQ31 -> 70.428062
A7: RNB25 | B7: 88.513502 | C7: 83.449414 | D7: 72.094609 | E7: 66.9275 | F7: 65.004897 | G7: 63.80457 | H7: 62.713812 | I7: 61.755096 | J7: 63.217986 | K7: 64.680876 | L7: 66.143766 | M7: 67.606656 | N7: 69.072152 | O7: 69.072152 | P7: 69.072152 | Q7: 69.072152 | R7: 69.072152 | S7: 69.072152 | T7: 69.072152 | U7: 69.072152 | V7: 69.072152 | W7: 69.072152 | X7: 69.072152 | Y7: 69.072152 | Z7: 69.072152 | AA7: 69.072152 | AB7: 69.072152 | AC7: 69.072152 | AD7: 69.072152 | AE7: 69.072152 | AF7: 69.072152 | AG7: 69.072152 | AH7: 69.072152 | AI7: 69.072152 | AJ7: 69.072152 | AK7: 69.072152 | AL7: 69.072152 | AM7: 69.072152 | AN7: 69.072152 | AO7: 69.072152 | AP7: 69.072152 | AQ7: 69.072152 | AR7: 69.072152 | AS7: 69.072152 | AT7: 69.072152 | AU7: 69.072152 | AV7: 69.072152 | AW7: 69.072152 | AX7: 69.072152 | AY7: 69.072152 | AZ7: 69.072152 | BA7: 69.072152 | BB7: 69.072152 | BC7: 69.072152 | BD7: 69.072152 | BE7: 69.072152 | BF7: 69.072152 | BG7: 69.072152 | BH7: 69.072152 | BI7: 69.072152 | BJ7: 69.072152 | BK7: 69.072152 | BL7: 69.072152 | BM7: 69.072152 | BN7: 69.072152 | BO7: 69.072152 | BP7: 69.072152 | BQ7: 69.072152
A9: Difference (Last round) | B9: =B6-B7 -> 1.7375669 | C9: =C6-C7 -> 1.5984142 | D9: =D6-D7 -> -0.34530905 | E9: =E6-E7 -> -0.235 | F9: =F6-F7 -> 0.26444662 | G9: =G6-G7 -> 0.48124226 | H9: =H6-H7 -> 0.5386789 | I9: =I6-I7 -> 0.29783318 | ... BQ9: =BQ6-BQ7 -> 1.3559098
A48: Oil price, fixed 2026-prices, NOK/fat | B48: Remark: If necessary you must adjust to the same price year with inflation forecast to the respective rounds
B49: 2023 | C49: 2024 | D49: 2025 | E49: 2026 | F49: 2027 | G49: 2028 | H49: 2029 | I49: 2030 | J49: 2031 | K49: 2032 | L49: 2033 | M49: 2034 | N49: 2035 | O49: 2036 | P49: 2037 | Q49: 2038 | R49: 2039 | S49: 2040 | T49: 2041 | U49: 2042 | V49: 2043 | W49: 2044 | X49: 2045 | Y49: 2046 | Z49: 2047 | AA49: 2048 | AB49: 2049 | AC49: 2050 | AD49: 2051 | AE49: 2052 | AF49: 2053 | AG49: 2054 | AH49: 2055 | AI49: 2056 | AJ49: 2057 | AK49: 2058 | AL49: 2059 | AM49: 2060 | AN49: 2061 | AO49: 2062 | AP49: 2063 | AQ49: 2064 | AR49: 2065 | AS49: 2066 | AT49: 2067 | AU49: 2068 | AV49: 2069 | AW49: 2070 | AX49: 2071 | AY49: 2072 | AZ49: 2073 | BA49: 2074 | BB49: 2075 | BC49: 2076 | BD49: 2077 | BE49: 2078 | BF49: 2079 | BG49: 2080 | BH49: 2081 | BI49: 2082 | BJ49: 2083 | BK49: 2084 | BL49: 2085 | BM49: 2086 | BN49: 2087 | BO49: 2088 | BP49: 2089 | BQ49: 2090
A50: NB26 | B50: =KVARTS!AB24 -> 953.37084 | C50: =KVARTS!AC24 -> 914.3073 | D50: =KVARTS!AD24 -> 746.45804 | E50: =KVARTS!AE24 -> 674.49527 | F50: =KVARTS!AF24 -> 660.10216 | G50: =KVARTS!AG24 -> 650.15521 | H50: =KVARTS!AH24 -> 639.7047 | I50: =KVARTS!AI24 -> 627.57292 | ... BQ50: =KVARTS!CQ24 -> 712.27491
A51: RNB25 | B51: 941.41394 | C51: 903.26221 | D51: 793.05191 | E51: 731.55542 | F51: 710.54028 | G51: 697.42003 | H51: 685.49742 | I51: 675.01812 | J51: 691.00833 | K51: 706.99855 | L51: 722.98876 | M51: 738.97898 | N51: 754.99768 | O51: 754.99768 | P51: 754.99768 | Q51: 754.99768 | R51: 754.99768 | S51: 754.99768 | T51: 754.99768 | U51: 754.99768 | V51: 754.99768 | W51: 754.99768 | X51: 754.99768 | Y51: 754.99768 | Z51: 754.99768 | AA51: 754.99768 | AB51: 754.99768 | AC51: 754.99768 | AD51: 754.99768 | AE51: 754.99768 | AF51: 754.99768 | AG51: 754.99768 | AH51: 754.99768 | AI51: 754.99768 | AJ51: 754.99768 | AK51: 754.99768 | AL51: 754.99768 | AM51: 754.99768 | AN51: 754.99768 | AO51: 754.99768 | AP51: 754.99768 | AQ51: 754.99768 | AR51: 754.99768 | AS51: 754.99768 | AT51: 754.99768 | AU51: 754.99768 | AV51: 754.99768 | AW51: 754.99768 | AX51: 754.99768 | AY51: 754.99768 | AZ51: 754.99768 | BA51: 754.99768 | BB51: 754.99768 | BC51: 754.99768 | BD51: 754.99768 | BE51: 754.99768 | BF51: 754.99768 | BG51: 754.99768 | BH51: 754.99768 | BI51: 754.99768 | BJ51: 754.99768 | BK51: 754.99768 | BL51: 754.99768 | BM51: 754.99768 | BN51: 754.99768 | BO51: 754.99768 | BP51: 754.99768 | BQ51: 754.99768
A53: Difference (Last round) | B53: =B50-B51 -> 11.9569 | C53: =C50-C51 -> 11.045088 | D53: =D50-D51 -> -46.593864 | E53: =E50-E51 -> -57.06015 | F53: =F50-F51 -> -50.438118 | G53: =G50-G51 -> -47.26482 | H53: =H50-H51 -> -45.792724 | I53: =I50-I51 -> -47.445196 | ... BQ53: =BQ50-BQ51 -> -42.722767
A90: Gas price, Fixed 2026-prices, NOK/Sm3 | B90: Remark: If necessary you must adjust to the same price year with inflation forecast to the respective rounds
B91: 2023 | C91: 2024 | D91: 2025 | E91: 2026 | F91: 2027 | G91: 2028 | H91: 2029 | I91: 2030 | J91: 2031 | K91: 2032 | L91: 2033 | M91: 2034 | N91: 2035 | O91: 2036 | P91: 2037 | Q91: 2038 | R91: 2039 | S91: 2040 | T91: 2041 | U91: 2042 | V91: 2043 | W91: 2044 | X91: 2045 | Y91: 2046 | Z91: 2047 | AA91: 2048 | AB91: 2049 | AC91: 2050 | AD91: 2051 | AE91: 2052 | AF91: 2053 | AG91: 2054 | AH91: 2055 | AI91: 2056 | AJ91: 2057 | AK91: 2058 | AL91: 2059 | AM91: 2060 | AN91: 2061 | AO91: 2062 | AP91: 2063 | AQ91: 2064 | AR91: 2065 | AS91: 2066 | AT91: 2067 | AU91: 2068 | AV91: 2069 | AW91: 2070 | AX91: 2071 | AY91: 2072 | AZ91: 2073 | BA91: 2074 | BB91: 2075 | BC91: 2076 | BD91: 2077 | BE91: 2078 | BF91: 2079 | BG91: 2080 | BH91: 2081 | BI91: 2082 | BJ91: 2083 | BK91: 2084 | BL91: 2085 | BM91: 2086 | BN91: 2087 | BO91: 2088 | BP91: 2089 | BQ91: 2090
A92: NB26 | B92: =KVARTS!AB25 -> 5.9850571 | C92: =KVARTS!AC25 -> 4.727289 | D92: =KVARTS!AD25 -> 5.3241062 | E92: =KVARTS!AE25 -> 3.9871306 | F92: =KVARTS!AF25 -> 3.1820369 | G92: =KVARTS!AG25 -> 3.1820369 | H92: =KVARTS!AH25 -> 3.1820369 | I92: =KVARTS!AI25 -> 2.5294211 | ... BQ92: =KVARTS!CQ25 -> 2.1921649
A93: RNB25 | B93: 5.8698293 | C93: 4.6275677 | D93: 5.5078414 | E93: 4.2099979 | F93: 3.3679983 | G93: 3.3679983 | H93: 3.3679983 | I93: 2.6629158 | J93: 2.6274087 | K93: 2.5919015 | L93: 2.5563944 | M93: 2.5208873 | N93: 2.4853802 | O93: 2.4498731 | P93: 2.4143659 | Q93: 2.3788588 | R93: 2.3433517 | S93: 2.3078604 | T93: 2.3078604 | U93: 2.3078604 | V93: 2.3078604 | W93: 2.3078604 | X93: 2.3078604 | Y93: 2.3078604 | Z93: 2.3078604 | AA93: 2.3078604 | AB93: 2.3078604 | AC93: 2.3078604 | AD93: 2.3078604 | AE93: 2.3078604 | AF93: 2.3078604 | AG93: 2.3078604 | AH93: 2.3078604 | AI93: 2.3078604 | AJ93: 2.3078604 | AK93: 2.3078604 | AL93: 2.3078604 | AM93: 2.3078604 | AN93: 2.3078604 | AO93: 2.3078604 | AP93: 2.3078604 | AQ93: 2.3078604 | AR93: 2.3078604 | AS93: 2.3078604 | AT93: 2.3078604 | AU93: 2.3078604 | AV93: 2.3078604 | AW93: 2.3078604 | AX93: 2.3078604 | AY93: 2.3078604 | AZ93: 2.3078604 | BA93: 2.3078604 | BB93: 2.3078604 | BC93: 2.3078604 | BD93: 2.3078604 | BE93: 2.3078604 | BF93: 2.3078604 | BG93: 2.3078604 | BH93: 2.3078604 | BI93: 2.3078604 | BJ93: 2.3078604 | BK93: 2.3078604 | BL93: 2.3078604 | BM93: 2.3078604 | BN93: 2.3078604 | BO93: 2.3078604 | BP93: 2.3078604 | BQ93: 2.3078604
A95: Difference (Last round) | B95: =B92-B93 -> 0.11522785 | C95: =C92-C93 -> 0.099721347 | D95: =D92-D93 -> -0.18373519 | E95: =E92-E93 -> -0.22286734 | F95: =F92-F93 -> -0.18596143 | G95: =G92-G93 -> -0.18596143 | H95: =H92-H93 -> -0.18596143 | I95: =I92-I93 -> -0.1334947 | ... BQ95: =BQ92-BQ93 -> -0.11569541
A132: Gas price, Fixed 2026-prices, USD/Mmbtu | C132: Remark: If necessary you must adjust to the same price year with inflation forecast to the respective rounds
B133: 2023 | C133: 2024 | D133: 2025 | E133: 2026 | F133: 2027 | G133: 2028 | H133: 2029 | I133: 2030 | J133: 2031 | K133: 2032 | L133: 2033 | M133: 2034 | N133: 2035 | O133: 2036 | P133: 2037 | Q133: 2038 | R133: 2039 | S133: 2040 | T133: 2041 | U133: 2042 | V133: 2043 | W133: 2044 | X133: 2045 | Y133: 2046 | Z133: 2047 | AA133: 2048 | AB133: 2049 | AC133: 2050 | AD133: 2051 | AE133: 2052 | AF133: 2053 | AG133: 2054 | AH133: 2055 | AI133: 2056 | AJ133: 2057 | AK133: 2058 | AL133: 2059 | AM133: 2060 | AN133: 2061 | AO133: 2062 | AP133: 2063 | AQ133: 2064 | AR133: 2065 | AS133: 2066 | AT133: 2067 | AU133: 2068 | AV133: 2069 | AW133: 2070 | AX133: 2071 | AY133: 2072 | AZ133: 2073 | BA133: 2074 | BB133: 2075 | BC133: 2076 | BD133: 2077 | BE133: 2078 | BF133: 2079 | BG133: 2080 | BH133: 2081 | BI133: 2082 | BJ133: 2083 | BK133: 2084 | BL133: 2085 | BM133: 2086 | BN133: 2087 | BO133: 2088 | BP133: 2089 | BQ133: 2090
A134: NB26 | B134: =KVARTS!AB27 -> 14.946296 | C134: =KVARTS!AC27 -> 11.6 | D134: =KVARTS!AD27 -> 13.5 | E134: =KVARTS!AE27 -> 10.4 | F134: =KVARTS!AF27 -> 8.3 | G134: =KVARTS!AG27 -> 8.3 | H134: =KVARTS!AH27 -> 8.3 | I134: =KVARTS!AI27 -> 6.5977221 | ... BQ134: =KVARTS!CQ27 -> 5.7180258
A135: RNB25 | B135: 14.658541 | C135: 11.3553 | D135: 13.299 | E135: 10.23 | F135: 8.184 | G135: 8.184 | H135: 8.184 | I135: 6.4706989 | J135: 6.384419 | K135: 6.2981392 | L135: 6.2118594 | M135: 6.1255796 | N135: 6.0392998 | O135: 5.9530199 | P135: 5.8667401 | Q135: 5.7804603 | R135: 5.6941805 | S135: 5.607939 | T135: 5.607939 | U135: 5.607939 | V135: 5.607939 | W135: 5.607939 | X135: 5.607939 | Y135: 5.607939 | Z135: 5.607939 | AA135: 5.607939 | AB135: 5.607939 | AC135: 5.607939 | AD135: 5.607939 | AE135: 5.607939 | AF135: 5.607939 | AG135: 5.607939 | AH135: 5.607939 | AI135: 5.607939 | AJ135: 5.607939 | AK135: 5.607939 | AL135: 5.607939 | AM135: 5.607939 | AN135: 5.607939 | AO135: 5.607939 | AP135: 5.607939 | AQ135: 5.607939 | AR135: 5.607939 | AS135: 5.607939 | AT135: 5.607939 | AU135: 5.607939 | AV135: 5.607939 | AW135: 5.607939 | AX135: 5.607939 | AY135: 5.607939 | AZ135: 5.607939 | BA135: 5.607939 | BB135: 5.607939 | BC135: 5.607939 | BD135: 5.607939 | BE135: 5.607939 | BF135: 5.607939 | BG135: 5.607939 | BH135: 5.607939 | BI135: 5.607939 | BJ135: 5.607939 | BK135: 5.607939 | BL135: 5.607939 | BM135: 5.607939 | BN135: 5.607939 | BO135: 5.607939 | BP135: 5.607939 | BQ135: 5.607939
A137: Difference (Last round) | B137: =B134-B135 -> 0.28775492 | C137: =C134-C135 -> 0.2447 | D137: =D134-D135 -> 0.201 | E137: =E134-E135 -> 0.17 | F137: =F134-F135 -> 0.116 | G137: =G134-G135 -> 0.116 | H137: =H134-H135 -> 0.116 | I137: =I134-I135 -> 0.12702324 | ... BQ137: =BQ134-BQ135 -> 0.11008681
A174: Oljeproduksjon, Mill. Sm3
B175: 2023 | C175: 2024 | D175: 2025 | E175: 2026 | F175: 2027 | G175: 2028 | H175: 2029 | I175: 2030 | J175: 2031 | K175: 2032 | L175: 2033 | M175: 2034 | N175: 2035 | O175: 2036 | P175: 2037 | Q175: 2038 | R175: 2039 | S175: 2040 | T175: 2041 | U175: 2042 | V175: 2043 | W175: 2044 | X175: 2045 | Y175: 2046 | Z175: 2047 | AA175: 2048 | AB175: 2049 | AC175: 2050 | AD175: 2051 | AE175: 2052 | AF175: 2053 | AG175: 2054 | AH175: 2055 | AI175: 2056 | AJ175: 2057 | AK175: 2058 | AL175: 2059 | AM175: 2060 | AN175: 2061 | AO175: 2062 | AP175: 2063 | AQ175: 2064 | AR175: 2065 | AS175: 2066 | AT175: 2067 | AU175: 2068 | AV175: 2069 | AW175: 2070 | AX175: 2071 | AY175: 2072 | AZ175: 2073 | BA175: 2074 | BB175: 2075 | BC175: 2076 | BD175: 2077 | BE175: 2078 | BF175: 2079 | BG175: 2080 | BH175: 2081 | BI175: 2082 | BJ175: 2083 | BK175: 2084 | BL175: 2085 | BM175: 2086 | BN175: 2087 | BO175: 2088 | BP175: 2089 | BQ175: 2090
A176: NB26 | B176: =Formue!Y30 -> 104.14 | C176: =Formue!Z30 -> 102.88638 | D176: =Formue!AA30 -> 105.18981 | E176: =Formue!AB30 -> 101.04576 | F176: =Formue!AC30 -> 96.575067 | G176: =Formue!AD30 -> 87.047892 | H176: =Formue!AE30 -> 78.845848 | I176: =Formue!AF30 -> 73.793909 | ... BQ176: =Formue!CN30 -> 28.071747
